Workbook
Name actual2m: actual2[[#All],[Month]:[Primary Deficit]]

Sheet Dashboard
C6: Financial Year | D6: 2025-26
C8: As at the end of | D8: Dec-25 | F8: =Sheet5!E9 -> 2525156 | I8: =IF(MONTH(D8)<4,Sheet5!N9,Sheet5!M9) -> 0.72221413 | J8: =Sheet5!K9 -> 0.089366071 | K8: =Sheet5!L9 -> 0.089366071 | M8: =Sheet5!E11 -> 3380998 | Q8: =IF(MONTH(D8)<4,Sheet5!N11,Sheet5!M11) -> 0.66747635 | R8: =Sheet5!K11 -> 0.046070442 | S8: =Sheet5!L11 -> 0.046070442 | U8: =Sheet5!E13 -> 855842
I9: =CONCATENATE("of ",B58) -> of BE | J9: YoY Growth | Q9: =CONCATENATE("of ",B58) -> of BE | R9: YoY Growth
U10: =IF(MONTH(D8)<4,Sheet5!N13,Sheet5!M13) -> 0.54549198 | W10: =CONCATENATE("of ",B58) -> of BE
U11: =Sheet5!O13 -> 0.023963844 | W11: of GDP
U12: =Sheet5!K13 -> -0.063721366 | W12: =Sheet5!L13 -> -0.063721366
U13: YoY Growth
F14: =Sheet5!E15 -> 1939254 | M14: =Sheet5!E21 -> 2593063
F15: =IF(MONTH(D8)<4,Sheet5!N15,Sheet5!M15) -> 0.68345945 | G15: =CONCATENATE("of ",B58) -> of BE | M15: =IF(MONTH(D8)<4,Sheet5!N21,Sheet5!M21) -> 0.65742783 | N15: =CONCATENATE("of ",B58) -> of BE
F16: =Sheet5!K15 -> 0.052196546 | H16: =Sheet5!L15 -> 0.052196546 | M16: =Sheet5!K21 -> 0.018182339 | O16: =Sheet5!L21 -> 0.018182339
F17: YoY Growth | M17: YoY Growth
U18: =Sheet5!E37 -> 113954
F20: Non Tax Revenue | U20: =IF(MONTH(D8)<4,Sheet5!N37,Sheet5!M37) -> 0.2175334 | W20: =CONCATENATE("of ",B58) -> of BE
U21: =Sheet5!O37 -> 0.0031907477 | W21: of GDP
F22: =Sheet5!E17 -> 539855 | U22: =Sheet5!K37 -> -0.5549489 | W22: =Sheet5!L37 -> -0.5549489
F23: =IF(MONTH(D8)<4,Sheet5!N17,Sheet5!M17) -> 0.92599485 | G23: =CONCATENATE("of ",B58) -> of BE | U23: YoY Growth
F24: =Sheet5!K17 -> 0.20595679 | H24: =Sheet5!L17 -> 0.20595679
F25: YoY Growth
U29: =Sheet5!E41 -> -55217
F31: =Sheet5!E19 -> 46047 | M31: =Sheet5!E23 -> 787935 | U31: =IF(MONTH(D8)<4,Sheet5!N41,Sheet5!M41) -> -0.18871284 | W31: =CONCATENATE("of ",B58) -> of BE
F32: =IF(MONTH(D8)<4,Sheet5!N19,Sheet5!M19) -> 0.60588158 | G32: =CONCATENATE("of ",B58) -> of BE | M32: =IF(MONTH(D8)<4,Sheet5!N23,Sheet5!M23) -> 0.70282939 | N32: =CONCATENATE("of ",B58) -> of BE | U32: =Sheet5!O41 -> -0.0015460933 | W32: of GDP
F33: =Sheet5!K19 -> 0.68701227 | H33: =Sheet5!L19 -> 0.68701227 | M33: =Sheet5!K23 -> 0.14970445 | O33: =Sheet5!L23 -> 0.14970445 | U33: =Sheet5!K41 -> -1.5220182 | W33: =Sheet5!L41 -> -1.5220182
F34: YoY Growth | M34: YoY Growth | U34: YoY Growth
B38: Disclaimer :
A39: 1. | B39: All content included in the dashboard is for informative purposes only. Information herein contains both original Budget, Expenditure, GDP data and estimates and is subject to updation, correction and revision with more information available.
A40: 2. | B40: The presentation of the graphical information herein does not imply the expression of any opinion concerning the performance, error, omission etc. of any institution or authorities.
A41: 3. | B41: Discrepancies between information contained in this dashboard and other documents, analysis, articles and publication may exist due to the different timing and presentation of information in accordance to various purposes.
A42: 4. | B42: This disclaimer of liability applies to all claims for damages, including, but not limited to: failure of performance, error, omission, deletion, defect, computer virus or unauthorized access to or alteration of data.
B43: Queries and feedback may be addressed to dama-cga@nic.in or vpthomas.17@gov.in
J53: =INDEX(actual!B:B,COUNTA(actual!B:B)) -> Dec-25 | M53: =DATEVALUE(J53)+1 -> 45993
B58: =IF(MONTH(D8)<4,"RE","BE") -> BE | D58: Row Labels | J58: =CONCATENATE("Apr-",MID($D$6,3,2)) -> Apr-25 | Q58: =IF(IF(DATEVALUE(CONCATENATE("Apr-",MID($D$6,3,2)))<$M$53,DATEVALUE(CONCATENATE("Apr-",MID($D$6,3,2))),0)>0,CONCATENATE("Apr-",MID($D$6,3,2))," ") -> Apr-25
D59: 2014-15 | J59: =CONCATENATE("May-",MID($D$6,3,2)) -> May-25 | Q59: =IF(IF(DATEVALUE(CONCATENATE("May-",MID($D$6,3,2)))<$M$53,DATEVALUE(CONCATENATE("May-",MID($D$6,3,2))),0)>0,CONCATENATE("May-",MID($D$6,3,2))," ") -> May-25
D60: 2015-16 | J60: =CONCATENATE("Jun-",MID($D$6,3,2)) -> Jun-25 | Q60: =IF(IF(DATEVALUE(CONCATENATE("Jun-",MID($D$6,3,2)))<$M$53,DATEVALUE(CONCATENATE("Jun-",MID($D$6,3,2))),0)>0,CONCATENATE("Jun-",MID($D$6,3,2))," ") -> Jun-25
D61: 2016-17 | J61: =CONCATENATE("Jul-",MID($D$6,3,2)) -> Jul-25 | Q61: =IF(IF(DATEVALUE(CONCATENATE("Jul-",MID($D$6,3,2)))<$M$53,DATEVALUE(CONCATENATE("Jul-",MID($D$6,3,2))),0)>0,CONCATENATE("Jul-",MID($D$6,3,2))," ") -> Jul-25
D62: 2017-18 | J62: =CONCATENATE("Aug-",MID($D$6,3,2)) -> Aug-25 | Q62: =IF(IF(DATEVALUE(CONCATENATE("Aug-",MID($D$6,3,2)))<$M$53,DATEVALUE(CONCATENATE("Aug-",MID($D$6,3,2))),0)>0,CONCATENATE("Aug-",MID($D$6,3,2))," ") -> Aug-25
D63: 2018-19 | J63: =CONCATENATE("Sep-",MID($D$6,3,2)) -> Sep-25 | Q63: =IF(IF(DATEVALUE(CONCATENATE("Sep-",MID($D$6,3,2)))<$M$53,DATEVALUE(CONCATENATE("Sep-",MID($D$6,3,2))),0)>0,CONCATENATE("Sep-",MID($D$6,3,2))," ") -> Sep-25
D64: 2019-20 | J64: =CONCATENATE("Oct-",MID($D$6,3,2)) -> Oct-25 | Q64: =IF(IF(DATEVALUE(CONCATENATE("Oct-",MID($D$6,3,2)))<$M$53,DATEVALUE(CONCATENATE("Oct-",MID($D$6,3,2))),0)>0,CONCATENATE("Oct-",MID($D$6,3,2))," ") -> Oct-25
D65: 2020-21 | J65: =CONCATENATE("Nov-",MID($D$6,3,2)) -> Nov-25 | Q65: =IF(IF(DATEVALUE(CONCATENATE("Nov-",MID($D$6,3,2)))<$M$53,DATEVALUE(CONCATENATE("Nov-",MID($D$6,3,2))),0)>0,CONCATENATE("Nov-",MID($D$6,3,2))," ") -> Nov-25
D66: 2021-22 | J66: =CONCATENATE("Dec-",MID($D$6,3,2)) -> Dec-25 | Q66: =IF(IF(DATEVALUE(CONCATENATE("Dec-",MID($D$6,3,2)))<$M$53,DATEVALUE(CONCATENATE("Dec-",MID($D$6,3,2))),0)>0,CONCATENATE("Dec-",MID($D$6,3,2))," ") -> Dec-25
D67: 2022-23 | J67: =CONCATENATE("Jan-",MID($D$6,6,2)) -> Jan-26 | Q67: =IF(IF(DATEVALUE(CONCATENATE("Jan-",MID($D$6,6,2)))<$M$53,DATEVALUE(CONCATENATE("Jan-",MID($D$6,6,2))),0)>0,CONCATENATE("Jan-",MID($D$6,6,2))," ")
...

Sheet Receipts

Sheet Expenditure

Sheet Deficit

Sheet actual
A1: FY | B1: Month | C1: Corporation Tax | D1: Income Tax | E1: Securities Transcation Tax | F1: CGST | G1: IGST | H1: UTGST | I1: Compensation Cess | J1: Customs | K1: Union Excise | L1: Service Tax | M1: Other Taxes | N1: Surcharge for financing of NCCF | O1: Devolution to State | P1: Interest receipts | Q1: Dividends and Profits | R1: Other Non Tax Receipts | S1: Recovery of Loans & Advances | T1: Disinvestment Receipts | U1: Revenue Expenditure | V1: Interest Payments | W1: Defence Services | X1: Grants in Aid to States & UTs | Y1: Pensions | Z1: Major Subsidies | AA1: Grants for Creation of Capital Assets | AB1: Capital Expenditure | AE1: Revenue Deficit | AF1: Effective revenue Deficit | AG1: Fiscal Deficit | AH1: Primary Deficit
A2: 2014-15 | B2: Apr-14 | C2: -5845 | D2: 20348 | E2: 168 | J2: 11754 | K2: -2817 | L2: 4876 | M2: 310 | N2: 122 | O2: 27695 | P2: 514 | Q2: 825 | R2: 4613 | S2: 144 | T2: 0 | U2: 108084 | V2: 23284 | W2: 19381 | X2: 962 | Y2: 5507 | Z2: 31779 | AA2: 10112 | AB2: 12443 | AD2: =SUM(actual1[[#This Row],[Corporation Tax]:[Other Taxes]])-actual1[[#This Row],[Surcharge for financing of NCCF]]-actual1[[#This Row],[Devolution to State]]+SUM(P2:R2)+SUM(S2:T2) -> 7073 | AE2: =actual1[[#This Row],[Revenue Expenditure]]-(SUM(actual1[[#This Row],[Corporation Tax]:[Other Taxes]])-actual1[[#This Row],[Surcharge for financing of NCCF]]-actual1[[#This Row],[Devolution to State]]+SUM(P2:R2)) -> 101155 | AF2: =AE2-actual1[[#This Row],[Grants for Creation of Capital Assets]] -> 91043 | AG2: =U2+AB2-(SUM(actual1[[#This Row],[Corporation Tax]:[Other Taxes]])-actual1[[#This Row],[Surcharge for financing of NCCF]]-actual1[[#This Row],[Devolution to State]]+SUM(P2:R2)+SUM(S2:T2)) -> 113454 | AH2: =AG2-actual1[[#This Row],[Interest Payments]] -> 90170
A3: 2014-15 | B3: May-14 | C3: 2980 | D3: 35449 | E3: 626 | J3: 24800 | K3: 5569 | L3: 14431 | M3: 661 | N3: 474 | O3: 55391 | P3: 645 | Q3: 837 | R3: 8372 | S3: 997 | T3: 0 | U3: 243585 | V3: 54857 | W3: 35705 | X3: 2122 | Y3: 14766 | Z3: 71250 | AA3: 21456 | AB3: 36754 | AD3: =U2+AB2 -> 120527 | AE3: =actual1[[#This Row],[Revenue Expenditure]]-(SUM(actual1[[#This Row],[Corporation Tax]:[Other Taxes]])-actual1[[#This Row],[Surcharge for financing of NCCF]]-actual1[[#This Row],[Devolution to State]]+SUM(P3:R3)) -> 205080 | AF3: =AE3-actual1[[#This Row],[Grants for Creation of Capital Assets]] -> 183624 | AG3: =U3+AB3-(SUM(actual1[[#This Row],[Corporation Tax]:[Other Taxes]])-actual1[[#This Row],[Surcharge for financing of NCCF]]-actual1[[#This Row],[Devolution to State]]+SUM(P3:R3)+SUM(S3:T3)) -> 240837 | AH3: =AG3-actual1[[#This Row],[Interest Payments]] -> 185980
A4: 2014-15 | B4: Jun-14 | C4: 50447 | D4: 46398 | E4: 1374 | J4: 38649 | K4: 18403 | L4: 26628 | M4: 1129 | N4: 856 | O4: 83086 | P4: 2005 | Q4: 2195 | R4: 11140 | S4: 1208 | T4: 109 | U4: 363785 | V4: 90694 | W4: 49351 | X4: 5501 | Y4: 22449 | Z4: 81443 | AA4: 32274 | AB4: 49818 | AE4: =actual1[[#This Row],[Revenue Expenditure]]-(SUM(actual1[[#This Row],[Corporation Tax]:[Other Taxes]])-actual1[[#This Row],[Surcharge for financing of NCCF]]-actual1[[#This Row],[Devolution to State]]+SUM(P4:R4)) -> 249359 | AF4: =AE4-actual1[[#This Row],[Grants for Creation of Capital Assets]] -> 217085 | AG4: =U4+AB4-(SUM(actual1[[#This Row],[Corporation Tax]:[Other Taxes]])-actual1[[#This Row],[Surcharge for financing of NCCF]]-actual1[[#This Row],[Devolution to State]]+SUM(P4:R4)+SUM(S4:T4)) -> 297860 | AH4: =AG4-actual1[[#This Row],[Interest Payments]] -> 207166
A5: 2014-15 | B5: Jul-14 | C5: 62518 | D5: 64905 | E5: 2067 | J5: 53881 | K5: 32264 | L5: 41628 | M5: 1610 | N5: 1227 | O5: 110781 | P5: 3546 | Q5: 3721 | R5: 21500 | S5: 3262 | T5: 122 | U5: 442051 | V5: 118615 | W5: 65913 | X5: 11908 | Y5: 29129 | Z5: 83557 | AA5: 36213 | AB5: 61889 | AE5: =actual1[[#This Row],[Revenue Expenditure]]-(SUM(actual1[[#This Row],[Corporation Tax]:[Other Taxes]])-actual1[[#This Row],[Surcharge for financing of NCCF]]-actual1[[#This Row],[Devolution to State]]+SUM(P5:R5)) -> 266419 | AF5: =AE5-actual1[[#This Row],[Grants for Creation of Capital Assets]] -> 230206 | AG5: =U5+AB5-(SUM(actual1[[#This Row],[Corporation Tax]:[Other Taxes]])-actual1[[#This Row],[Surcharge for financing of NCCF]]-actual1[[#This Row],[Devolution to State]]+SUM(P5:R5)+SUM(S5:T5)) -> 324924 | AH5: =AG5-actual1[[#This Row],[Interest Payments]] -> 206309
A6: 2014-15 | B6: Aug-14 | C6: 73569 | D6: 78535 | E6: 2717 | J6: 69838 | K6: 45453 | L6: 52817 | M6: 2009 | N6: 1555 | O6: 137924 | P6: 4440 | Q6: 56274 | R6: 24282 | S6: 4212 | T6: 122 | U6: 595219 | V6: 153876 | W6: 82049 | X6: 18024 | Y6: 38354 | Z6: 125762 | AA6: 53551 | AB6: 77499 | AE6: =actual1[[#This Row],[Revenue Expenditure]]-(SUM(actual1[[#This Row],[Corporation Tax]:[Other Taxes]])-actual1[[#This Row],[Surcharge for financing of NCCF]]-actual1[[#This Row],[Devolution to State]]+SUM(P6:R6)) -> 324764 | AF6: =AE6-actual1[[#This Row],[Grants for Creation of Capital Assets]] -> 271213 | AG6: =U6+AB6-(SUM(actual1[[#This Row],[Corporation Tax]:[Other Taxes]])-actual1[[#This Row],[Surcharge for financing of NCCF]]-actual1[[#This Row],[Devolution to State]]+SUM(P6:R6)+SUM(S6:T6)) -> 397929 | AH6: =AG6-actual1[[#This Row],[Interest Payments]] -> 244053
A7: 2014-15 | B7: Sep-14 | C7: 162269 | D7: 109412 | E7: 3223 | J7: 87408 | K7: 60547 | L7: 65201 | M7: 2558 | N7: 2012 | O7: 165415 | P7: 6347 | Q7: 61388 | R7: 26970 | S7: 5210 | T7: 121 | U7: 762949 | V7: 185670 | W7: 102021 | X7: 24324 | Y7: 46206 | Z7: 160133 | AA7: 66269 | AB7: 99104 | AE7: =actual1[[#This Row],[Revenue Expenditure]]-(SUM(actual1[[#This Row],[Corporation Tax]:[Other Taxes]])-actual1[[#This Row],[Surcharge for financing of NCCF]]-actual1[[#This Row],[Devolution to State]]+SUM(P7:R7)) -> 345053 | AF7: =AE7-actual1[[#This Row],[Grants for Creation of Capital Assets]] -> 278784 | AG7: =U7+AB7-(SUM(actual1[[#This Row],[Corporation Tax]:[Other Taxes]])-actual1[[#This Row],[Surcharge for financing of NCCF]]-actual1[[#This Row],[Devolution to State]]+SUM(P7:R7)+SUM(S7:T7)) -> 438826 | AH7: =AG7-actual1[[#This Row],[Interest Payments]] -> 253156
A8: 2014-15 | B8: Oct-14 | C8: 173381 | D8: 124972 | E8: 3876 | J8: 104104 | K8: 73105 | L8: 81213 | M8: 2947 | N8: 2515 | O8: 192211 | P8: 10651 | Q8: 63856 | R8: 36694 | S8: 6142 | T8: 122 | U8: 852707 | V8: 205974 | W8: 119070 | X8: 28317 | Y8: 53737 | Z8: 178105 | AA8: 73705 | AB8: 109382 | AE8: =actual1[[#This Row],[Revenue Expenditure]]-(SUM(actual1[[#This Row],[Corporation Tax]:[Other Taxes]])-actual1[[#This Row],[Surcharge for financing of NCCF]]-actual1[[#This Row],[Devolution to State]]+SUM(P8:R8)) -> 372634 | AF8: =AE8-actual1[[#This Row],[Grants for Creation of Capital Assets]] -> 298929 | AG8: =U8+AB8-(SUM(actual1[[#This Row],[Corporation Tax]:[Other Taxes]])-actual1[[#This Row],[Surcharge for financing of NCCF]]-actual1[[#This Row],[Devolution to State]]+SUM(P8:R8)+SUM(S8:T8)) -> 475752 | AH8: =AG8-actual1[[#This Row],[Interest Payments]] -> 269778
A9: 2014-15 | B9: Nov-14 | C9: 188553 | D9: 140150 | E9: 4357 | J9: 120225 | K9: 85925 | L9: 92903 | M9: 3470 | N9: 2918 | O9: 219355 | P9: 11629 | Q9: 63959 | R9: 52755 | S9: 7174 | T9: 222 | U9: 952728 | V9: 232650 | W9: 135526 | X9: 33124 | Y9: 61316 | Z9: 195504 | AA9: 81584 | AB9: 121455 | AE9: =actual1[[#This Row],[Revenue Expenditure]]-(SUM(actual1[[#This Row],[Corporation Tax]:[Other Taxes]])-actual1[[#This Row],[Surcharge for financing of NCCF]]-actual1[[#This Row],[Devolution to State]]+SUM(P9:R9)) -> 411075 | AF9: =AE9-actual1[[#This Row],[Grants for Creation of Capital Assets]] -> 329491 | AG9: =U9+AB9-(SUM(actual1[[#This Row],[Corporation Tax]:[Other Taxes]])-actual1[[#This Row],[Surcharge for financing of NCCF]]-actual1[[#This Row],[Devolution to State]]+SUM(P9:R9)+SUM(S9:T9)) -> 525134 | AH9: =AG9-actual1[[#This Row],[Interest Payments]] -> 292484
A10: 2014-15 | B10: Dec-14 | C10: 277620 | D10: 166556 | E10: 4939 | J10: 135596 | K10: 101859 | L10: 105196 | M10: 3920 | N10: 3362 | O10: 246610 | P10: 15808 | Q10: 69674 | R10: 62577 | S10: 8282 | T10: 1952 | U10: 1095548 | V10: 275220 | W10: 157318 | X10: 34598 | Y10: 68104 | Z10: 212418 | AA10: 97863 | AB10: 140840 | AE10: =actual1[[#This Row],[Revenue Expenditure]]-(SUM(actual1[[#This Row],[Corporation Tax]:[Other Taxes]])-actual1[[#This Row],[Surcharge for financing of NCCF]]-actual1[[#This Row],[Devolution to State]]+SUM(P10:R10)) -> 401775 | AF10: =AE10-actual1[[#This Row],[Grants for Creation of Capital Assets]] -> 303912 | AG10: =U10+AB10-(SUM(actual1[[#This Row],[Corporation Tax]:[Other Taxes]])-actual1[[#This Row],[Surcharge for financing of NCCF]]-actual1[[#This Row],[Devolution to State]]+SUM(P10:R10)+SUM(S10:T10)) -> 532381 | AH10: =AG10-actual1[[#This Row],[Interest Payments]] -> 257161
A11: 2014-15 | B11: Jan-15 | C11: 287720 | D11: 182077 | E11: 5556 | J11: 151849 | K11: 118109 | L11: 122450 | M11: 4323 | N11: 3645 | O11: 273642 | P11: 17236 | Q11: 70019 | R11: 71055 | S11: 9954 | T11: 7068 | U11: 1194613 | V11: 312260 | W11: 174307 | X11: 37023 | Y11: 76133 | Z11: 231788 | AA11: 102208 | AB11: 143655 | AE11: =actual1[[#This Row],[Revenue Expenditure]]-(SUM(actual1[[#This Row],[Corporation Tax]:[Other Taxes]])-actual1[[#This Row],[Surcharge for financing of NCCF]]-actual1[[#This Row],[Devolution to State]]+SUM(P11:R11)) -> 441506 | AF11: =AE11-actual1[[#This Row],[Grants for Creation of Capital Assets]] -> 339298 | AG11: =U11+AB11-(SUM(actual1[[#This Row],[Corporation Tax]:[Other Taxes]])-actual1[[#This Row],[Surcharge for financing of NCCF]]-actual1[[#This Row],[Devolution to State]]+SUM(P11:R11)+SUM(S11:T11)) -> 568139 | AH11: =AG11-actual1[[#This Row],[Interest Payments]] -> 255879
A12: 2014-15 | B12: Feb-15 | C12: 301761 | D12: 199496 | E12: 6280 | J12: 167492 | K12: 140322 | L12: 134889 | M12: 4713 | N12: 4035 | O12: 299499 | P12: 18561 | Q12: 72397 | R12: 73861 | S12: 11063 | T12: 29701 | U12: 1299492 | V12: 346256 | W12: 193989 | X12: 46673 | Y12: 80321 | Z12: 237878 | AA12: 114070 | AB12: 160044 | AE12: =actual1[[#This Row],[Revenue Expenditure]]-(SUM(actual1[[#This Row],[Corporation Tax]:[Other Taxes]])-actual1[[#This Row],[Surcharge for financing of NCCF]]-actual1[[#This Row],[Devolution to State]]+SUM(P12:R12)) -> 483254 | AF12: =AE12-actual1[[#This Row],[Grants for Creation of Capital Assets]] -> 369184 | AG12: =U12+AB12-(SUM(actual1[[#This Row],[Corporation Tax]:[Other Taxes]])-actual1[[#This Row],[Surcharge for financing of NCCF]]-actual1[[#This Row],[Devolution to State]]+SUM(P12:R12)+SUM(S12:T12)) -> 602534 | AH12: =AG12-actual1[[#This Row],[Interest Payments]] -> 256278
A13: 2014-15 | B13: Mar-15 | C13: 428925 | D13: 258334 | E13: 7398 | J13: 188016 | K13: 189953 | L13: 167969 | M13: 4289 | N13: 3461 | O13: 337808 | P13: 23734 | Q13: 89861 | R13: 84171 | S13: 13738 | T13: 37737 | U13: 1466992 | V13: 402444 | W13: 218694 | X13: 77198 | Y13: 93611 | Z13: 249220 | AA13: 130760 | AB13: 196681 | AE13: =actual1[[#This Row],[Revenue Expenditure]]-(SUM(actual1[[#This Row],[Corporation Tax]:[Other Taxes]])-actual1[[#This Row],[Surcharge for financing of NCCF]]-actual1[[#This Row],[Devolution to State]]+SUM(P13:R13)) -> 365611 | AF13: =AE13-actual1[[#This Row],[Grants for Creation of Capital Assets]] -> 234851 | AG13: =U13+AB13-(SUM(actual1[[#This Row],[Corporation Tax]:[Other Taxes]])-actual1[[#This Row],[Surcharge for financing of NCCF]]-actual1[[#This Row],[Devolution to State]]+SUM(P13:R13)+SUM(S13:T13)) -> 510817 | AH13: =AG13-actual1[[#This Row],[Interest Payments]] -> 108373
A14: 2015-16 | B14: Apr-15 | C14: -4319 | D14: 19878 | E14: 268 | J14: 14452 | K14: -2696 | L14: 6874 | M14: 359 | N14: 208 | O14: 37421 | P14: 768 | Q14: 1 | R14: 27357 | S14: 173 | T14: 1608 | U14: 128408 | V14: 16994 | W14: 18512 | X14: 4856 | Y14: 9031 | Z14: 41130 | AA14: 18367 | AB14: 26209 | AE14: =actual1[[#This Row],[Revenue Expenditure]]-(SUM(actual1[[#This Row],[Corporation Tax]:[Other Taxes]])-actual1[[#This Row],[Surcharge for financing of NCCF]]-actual1[[#This Row],[Devolution to State]]+SUM(P14:R14)) -> 103095 | AF14: =AE14-actual1[[#This Row],[Grants for Creation of Capital Assets]] -> 84728 | AG14: =U14+AB14-(SUM(actual1[[#This Row],[Corporation Tax]:[Other Taxes]])-actual1[[#This Row],[Surcharge for financing of NCCF]]-actual1[[#This Row],[Devolution to State]]+SUM(P14:R14)+SUM(S14:T14)) -> 127523 | AH14: =AG14-actual1[[#This Row],[Interest Payments]] -> 110529
A15: 2015-16 | B15: May-15 | C15: 1047 | D15: 31604 | E15: 939 | J15: 29907 | K15: 13649 | L15: 17411 | M15: 775 | N15: 596 | O15: 74847 | P15: 1535 | Q15: 5 | R15: 30932 | S15: 238 | T15: 1608 | U15: 225088 | V15: 48447 | W15: 34670 | X15: 13137 | Y15: 15671 | Z15: 49557 | AA15: 22138 | AB15: 37743 | AE15: =actual1[[#This Row],[Revenue Expenditure]]-(SUM(actual1[[#This Row],[Corporation Tax]:[Other Taxes]])-actual1[[#This Row],[Surcharge for financing of NCCF]]-actual1[[#This Row],[Devolution to State]]+SUM(P15:R15)) -> 172727 | AF15: =AE15-actual1[[#This Row],[Grants for Creation of Capital Assets]] -> 150589 | AG15: =U15+AB15-(SUM(actual1[[#This Row],[Corporation Tax]:[Other Taxes]])-actual1[[#This Row],[Surcharge for financing of NCCF]]-actual1[[#This Row],[Devolution to State]]+SUM(P15:R15)+SUM(S15:T15)) -> 208624 | AH15: =AG15-actual1[[#This Row],[Interest Payments]] -> 160177
... A28: 2016-17 | B28: Jun-16 | C28: 54110 | D28: 69140 | E28: 1438 | J28: 55528 | K28: 60273 | L28: 39086 | M28: 1278 | N28: 1339 | O28: 122211 | P28: 1868 | Q28: 4221 | R28: 17395 | S28: 1743 | T28: 2979 | U28: 462836 | V28: 108802 | W28: 40230 | X28: 95327 | Y28: 27863 | Z28: 92287 | AA28: 53773 | AB28: 48996 | AE28: =actual1[[#This Row],[Revenue Expenditure]]-(SUM(actual1[[#This Row],[Corporation Tax]:[Other Taxes]])-actual1[[#This Row],[Surcharge for financing of NCCF]]-actual1[[#This Row],[Devolution to State]]+SUM(P28:R28)) -> 282049 | AF28: =AE28-actual1[[#This Row],[Grants for Creation of Capital Assets]] -> 228276 | AG28: =U28+AB28-(SUM(actual1[[#This Row],[Corporation Tax]:[Other Taxes]])-actual1[[#This Row],[Surcharge for financing of NCCF]]-actual1[[#This Row],[Devolution to State]]+SUM(P28:R28)+SUM(S28:T28)) -> 326323 | AH28: =AG28-actual1[[#This Row],[Interest Payments]] -> 217521
A29: 2016-17 | B29: Jul-16 | C29: 67061 | D29: 91834 | E29: 1952 | F29: 0 | G29: 0 | H29: 0 | I29: 0 | J29: 72153 | K29: 90328 | L29: 61195 | M29: 1916 | N29: 1822 | O29: 162949 | P29: 2866 | Q29: 4522 | R29: 26710 | S29: 4251 | T29: 3183 | U29: 585404 | V29: 140479 | W29: 52565 | X29: 119808 | Y29: 36867 | Z29: 105879 | AA29: 63211 | AB29: 71283 | AE29: =actual1[[#This Row],[Revenue Expenditure]]-(SUM(actual1[[#This Row],[Corporation Tax]:[Other Taxes]])-actual1[[#This Row],[Surcharge for financing of NCCF]]-actual1[[#This Row],[Devolution to State]]+SUM(P29:R29)) -> 329638 | AF29: =AE29-actual1[[#This Row],[Grants for Creation of Capital Assets]] -> 266427 | AG29: =U29+AB29-(SUM(actual1[[#This Row],[Corporation Tax]:[Other Taxes]])-actual1[[#This Row],[Surcharge for financing of NCCF]]-actual1[[#This Row],[Devolution to State]]+SUM(P29:R29)+SUM(S29:T29)) -> 393487 | AH29: =AG29-actual1[[#This Row],[Interest Payments]] -> 253008
A30: 2016-17 | B30: Aug-16 | C30: 80464 | D30: 109918 | E30: 2812 | F30: 0 | G30: 0 | H30: 0 | I30: 0 | J30: 90774 | K30: 120935 | L30: 79039 | M30: 2414 | N30: 2413 | O30: 203688 | P30: 3891 | Q30: 70678 | R30: 30499 | S30: 5335 | T30: 3183 | U30: 710329 | V30: 174472 | W30: 65949 | X30: 147192 | Y30: 48052 | Z30: 115219 | AA30: 70380 | AB30: 91332 | AE30: =actual1[[#This Row],[Revenue Expenditure]]-(SUM(actual1[[#This Row],[Corporation Tax]:[Other Taxes]])-actual1[[#This Row],[Surcharge for financing of NCCF]]-actual1[[#This Row],[Devolution to State]]+SUM(P30:R30)) -> 325006 | AF30: =AE30-actual1[[#This Row],[Grants for Creation of Capital Assets]] -> 254626 | AG30: =U30+AB30-(SUM(actual1[[#This Row],[Corporation Tax]:[Other Taxes]])-actual1[[#This Row],[Surcharge for financing of NCCF]]-actual1[[#This Row],[Devolution to State]]+SUM(P30:R30)+SUM(S30:T30)) -> 407820 | AH30: =AG30-actual1[[#This Row],[Interest Payments]] -> 233348
A31: 2016-17 | B31: Sep-16 | C31: 186789 | D31: 144233 | E31: 3607 | F31: 0 | G31: 0 | H31: 0 | I31: 0 | J31: 109087 | K31: 152347 | L31: 96673 | M31: 2957 | N31: 3111 | O31: 244427 | P31: 6223 | Q31: 79046 | R31: 33499 | S31: 6802 | T31: 6015 | U31: 892803 | V31: 213229 | W31: 78764 | X31: 188886 | Y31: 59643 | Z31: 142643 | AA31: 100762 | AB31: 134925 | AE31: =actual1[[#This Row],[Revenue Expenditure]]-(SUM(actual1[[#This Row],[Corporation Tax]:[Other Taxes]])-actual1[[#This Row],[Surcharge for financing of NCCF]]-actual1[[#This Row],[Devolution to State]]+SUM(P31:R31)) -> 325880 | AF31: =AE31-actual1[[#This Row],[Grants for Creation of Capital Assets]] -> 225118 | AG31: =U31+AB31-(SUM(actual1[[#This Row],[Corporation Tax]:[Other Taxes]])-actual1[[#This Row],[Surcharge for financing of NCCF]]-actual1[[#This Row],[Devolution to State]]+SUM(P31:R31)+SUM(S31:T31)) -> 447988 | AH31: =AG31-actual1[[#This Row],[Interest Payments]] -> 234759
A32: 2016-17 | B32: Oct-16 | C32: 207334 | D32: 169891 | E32: 4416 | F32: 0 | G32: 0 | H32: 0 | I32: 0 | J32: 127971 | K32: 180663 | L32: 124912 | M32: 3697 | N32: 3703 | O32: 285166 | P32: 7581 | Q32: 83225 | R32: 77167 | S32: 7938 | T32: 21410 | U32: 1025884 | V32: 226807 | W32: 99185 | X32: 207331 | Y32: 70097 | Z32: 192395 | AA32: 105256 | AB32: 124959 | AE32: =actual1[[#This Row],[Revenue Expenditure]]-(SUM(actual1[[#This Row],[Corporation Tax]:[Other Taxes]])-actual1[[#This Row],[Surcharge for financing of NCCF]]-actual1[[#This Row],[Devolution to State]]+SUM(P32:R32)) -> 327896 | AF32: =AE32-actual1[[#This Row],[Grants for Creation of Capital Assets]] -> 222640 | AG32: =U32+AB32-(SUM(actual1[[#This Row],[Corporation Tax]:[Other Taxes]])-actual1[[#This Row],[Surcharge for financing of NCCF]]-actual1[[#This Row],[Devolution to State]]+SUM(P32:R32)+SUM(S32:T32)) -> 423507 | AH32: =AG32-actual1[[#This Row],[Interest Payments]] -> 196700
A33: 2016-17 | B33: Nov-16 | C33: 222258 | D33: 186675 | E33: 5109 | F33: 0 | G33: 0 | H33: 0 | I33: 0 | J33: 148501 | K33: 213584 | L33: 146839 | M33: 10314 | N33: 4294 | O33: 307814 | P33: 9007 | Q33: 86460 | R33: 79484 | S33: 9033 | T33: 23529 | U33: 1144334 | V33: 266678 | W33: 111244 | X33: 221296 | Y33: 81111 | Z33: 197791 | AA33: 112921 | AB33: 142347 | AE33: =actual1[[#This Row],[Revenue Expenditure]]-(SUM(actual1[[#This Row],[Corporation Tax]:[Other Taxes]])-actual1[[#This Row],[Surcharge for financing of NCCF]]-actual1[[#This Row],[Devolution to State]]+SUM(P33:R33)) -> 348211 | AF33: =AE33-actual1[[#This Row],[Grants for Creation of Capital Assets]] -> 235290 | AG33: =U33+AB33-(SUM(actual1[[#This Row],[Corporation Tax]:[Other Taxes]])-actual1[[#This Row],[Surcharge for financing of NCCF]]-actual1[[#This Row],[Devolution to State]]+SUM(P33:R33)+SUM(S33:T33)) -> 457996 | AH33: =AG33-actual1[[#This Row],[Interest Payments]] -> 191318
A34: 2016-17 | B34: Dec-16 | C34: 320280 | D34: 224241 | E34: 5931 | F34: 0 | G34: 0 | H34: 0 | I34: 0 | J34: 167294 | K34: 246335 | L34: 163646 | M34: 11360 | N34: 4864 | O34: 382107 | P34: 10787 | Q34: 86908 | R34: 84755 | S34: 10403 | T34: 23529 | U34: 1288862 | V34: 325684 | W34: 126595 | X34: 251796 | Y34: 93394 | Z34: 214320 | AA34: 125523 | AB34: 180886 | AE34: =actual1[[#This Row],[Revenue Expenditure]]-(SUM(actual1[[#This Row],[Corporation Tax]:[Other Taxes]])-actual1[[#This Row],[Surcharge for financing of NCCF]]-actual1[[#This Row],[Devolution to State]]+SUM(P34:R34)) -> 354296 | AF34: =AE34-actual1[[#This Row],[Grants for Creation of Capital Assets]] -> 228773 | AG34: =U34+AB34-(SUM(actual1[[#This Row],[Corporation Tax]:[Other Taxes]])-actual1[[#This Row],[Surcharge for financing of NCCF]]-actual1[[#This Row],[Devolution to State]]+SUM(P34:R34)+SUM(S34:T34)) -> 501250 | AH34: =AG34-actual1[[#This Row],[Interest Payments]] -> 175566
A35: 2016-17 | B35: Jan-17 | C35: 327303 | D35: 245413 | E35: 6523 | F35: 0 | G35: 0 | H35: 0 | I35: 0 | J35: 186291 | K35: 278330 | L35: 188752 | M35: 12058 | N35: 5470 | O35: 422846 | P35: 12842 | Q35: 88325 | R35: 91873 | S35: 13057 | T35: 31014 | U35: 1414220 | V35: 368592 | W35: 140910 | X35: 275458 | Y35: 113148 | Z35: 216266 | AA35: 135063 | AB35: 203437 | AE35: =actual1[[#This Row],[Revenue Expenditure]]-(SUM(actual1[[#This Row],[Corporation Tax]:[Other Taxes]])-actual1[[#This Row],[Surcharge for financing of NCCF]]-actual1[[#This Row],[Devolution to State]]+SUM(P35:R35)) -> 404826 | AF35: =AE35-actual1[[#This Row],[Grants for Creation of Capital Assets]] -> 269763 | AG35: =U35+AB35-(SUM(actual1[[#This Row],[Corporation Tax]:[Other Taxes]])-actual1[[#This Row],[Surcharge for financing of NCCF]]-actual1[[#This Row],[Devolution to State]]+SUM(P35:R35)+SUM(S35:T35)) -> 564192 | AH35: =AG35-actual1[[#This Row],[Interest Payments]] -> 195600
A36: 2016-17 | B36: Feb-17 | C36: 343945 | D36: 268313 | E36: 7218 | F36: 0 | G36: 0 | H36: 0 | I36: 0 | J36: 203880 | K36: 312241 | L36: 206673 | M36: 12672 | N36: 6085 | O36: 463585 | P36: 13775 | Q36: 96957 | R36: 98179 | S36: 14180 | T36: 39043 | U36: 1538224 | V36: 403984 | W36: 154043 | X36: 295708 | Y36: 123174 | Z36: 226746 | AA36: 145377 | AB36: 214796 | AE36: =actual1[[#This Row],[Revenue Expenditure]]-(SUM(actual1[[#This Row],[Corporation Tax]:[Other Taxes]])-actual1[[#This Row],[Surcharge for financing of NCCF]]-actual1[[#This Row],[Devolution to State]]+SUM(P36:R36)) -> 444041 | AF36: =AE36-actual1[[#This Row],[Grants for Creation of Capital Assets]] -> 298664 | AG36: =U36+AB36-(SUM(actual1[[#This Row],[Corporation Tax]:[Other Taxes]])-actual1[[#This Row],[Surcharge for financing of NCCF]]-actual1[[#This Row],[Devolution to State]]+SUM(P36:R36)+SUM(S36:T36)) -> 605614 | AH36: =AG36-actual1[[#This Row],[Interest Payments]] -> 201630
A37: 2016-17 | B37: Mar-17 | C37: 484924 | D37: 340592 | E37: 8998 | F37: 0 | G37: 0 | H37: 0 | I37: 0 | J37: 225370 | K37: 380496 | L37: 254499 | M37: 20943 | N37: 6450 | O37: 608000 | P37: 16264 | Q37: 123021 | R37: 135299 | S37: 17770 | T37: 47743 | U37: 1692986 | V37: 480714 | W37: 165410 | X37: 285876 | Y37: 131401 | Z37: 206666 | AA37: 166560 | AB37: 286282 | AE37: =actual1[[#This Row],[Revenue Expenditure]]-(SUM(actual1[[#This Row],[Corporation Tax]:[Other Taxes]])-actual1[[#This Row],[Surcharge for financing of NCCF]]-actual1[[#This Row],[Devolution to State]]+SUM(P37:R37)) -> 317030 | AF37: =AE37-actual1[[#This Row],[Grants for Creation of Capital Assets]] -> 150470 | AG37: =U37+AB37-(SUM(actual1[[#This Row],[Corporation Tax]:[Other Taxes]])-actual1[[#This Row],[Surcharge for financing of NCCF]]-actual1[[#This Row],[Devolution to State]]+SUM(P37:R37)+SUM(S37:T37)) -> 537799 | AH37: =AG37-actual1[[#This Row],[Interest Payments]] -> 57085
A38: 2017-18 | B38: Apr-17 | C38: 6266 | D38: 33310 | E38: 410 | F38: 0 | G38: 0 | H38: 0 | I38: 0 | J38: 20574 | K38: 1323 | L38: 8901 | M38: 613 | N38: 187 | O38: 48178 | P38: 426 | Q38: 15 | R38: 11608 | S38: 255 | T38: 1193 | U38: 213464 | V38: 19422 | W38: 17828 | X38: 35733 | Y38: 17855 | Z38: 79480 | AA38: 24666 | AB38: 28687 | AE38: =actual1[[#This Row],[Revenue Expenditure]]-(SUM(actual1[[#This Row],[Corporation Tax]:[Other Taxes]])-actual1[[#This Row],[Surcharge for financing of NCCF]]-actual1[[#This Row],[Devolution to State]]+SUM(P38:R38)) -> 178383 | AF38: =AE38-actual1[[#This Row],[Grants for Creation of Capital Assets]] -> 153717 | AG38: =U38+AB38-(SUM(actual1[[#This Row],[Corporation Tax]:[Other Taxes]])-actual1[[#This Row],[Surcharge for financing of NCCF]]-actual1[[#This Row],[Devolution to State]]+SUM(P38:R38)+SUM(S38:T38)) -> 205622 | AH38: =AG38-actual1[[#This Row],[Interest Payments]] -> 186200
A39: 2017-18 | B39: May-17 | C39: 13482 | D39: 50275 | E39: 1189 | F39: 0 | G39: 0 | H39: 0 | I39: 0 | J39: 43058 | K39: 30778 | L39: 24958 | M39: 1093 | N39: 804 | O39: 96361 | P39: 696 | Q39: 16 | R39: 14632 | S39: 398 | T39: 2255 | U39: 406490 | V39: 69014 | W39: 39548 | X39: 63029 | Y39: 36027 | Z39: 117215 | AA39: 42805 | AB39: 52536 | AE39: =actual1[[#This Row],[Revenue Expenditure]]-(SUM(actual1[[#This Row],[Corporation Tax]:[Other Taxes]])-actual1[[#This Row],[Surcharge for financing of NCCF]]-actual1[[#This Row],[Devolution to State]]+SUM(P39:R39)) -> 323478 | AF39: =AE39-actual1[[#This Row],[Grants for Creation of Capital Assets]] -> 280673 | AG39: =U39+AB39-(SUM(actual1[[#This Row],[Corporation Tax]:[Other Taxes]])-actual1[[#This Row],[Surcharge for financing of NCCF]]-actual1[[#This Row],[Devolution to State]]+SUM(P39:R39)+SUM(S39:T39)) -> 373361 | AH39: =AG39-actual1[[#This Row],[Interest Payments]] -> 304347
A40: 2017-18 | B40: Jun-17 | C40: 67259 | D40: 76497 | E40: 2147 | F40: 0 | G40: 0 | H40: 0 | I40: 0 | J40: 63859 | K40: 64673 | L40: 47048 | M40: 1937 | N40: 1538 | O40: 144545 | P40: 1487 | Q40: 1297 | R40: 19181 | S40: 2054 | T40: 7690 | U40: 582403 | V40: 133410 | W40: 56447 | X40: 95816 | Y40: 48090 | Z40: 135450 | AA40: 55515 | AB40: 68328 | AE40: =actual1[[#This Row],[Revenue Expenditure]]-(SUM(actual1[[#This Row],[Corporation Tax]:[Other Taxes]])-actual1[[#This Row],[Surcharge for financing of NCCF]]-actual1[[#This Row],[Devolution to State]]+SUM(P40:R40)) -> 383101 | AF40: =AE40-actual1[[#This Row],[Grants for Creation of Capital Assets]] -> 327586 | AG40: =U40+AB40-(SUM(actual1[[#This Row],[Corporation Tax]:[Other Taxes]])-actual1[[#This Row],[Surcharge for financing of NCCF]]-actual1[[#This Row],[Devolution to State]]+SUM(P40:R40)+SUM(S40:T40)) -> 441685 | AH40: =AG40-actual1[[#This Row],[Interest Payments]] -> 308275
... A120: 2023-24 | B120: Feb-24 | C120: 752718 | D120: 812371 | E120: 29804 | F120: 747515 | G120: -43291 | H120: 4336 | I120: 128727 | J120: 196352 | K120: 253835 | L120: 467 | M120: 7017 | N120: 6966 | O120: 1033433 | P120: 34036 | Q120: 157070 | R120: 169224 | S120: 23480 | T120: 12660 | U120: 2941674 | V120: 880788 | W120: 269224 | X120: 465234 | Y120: 232075 | Z120: 360997 | AA120: 254355 | AB120: 805613 | AE120: =actual1[[#This Row],[Revenue Expenditure]]-(SUM(actual1[[#This Row],[Corporation Tax]:[Other Taxes]])-actual1[[#This Row],[Surcharge for financing of NCCF]]-actual1[[#This Row],[Devolution to State]]+SUM(P120:R120)) -> 731892 | AF120: =AE120-actual1[[#This Row],[Grants for Creation of Capital Assets]] -> 477537 | AG120: =U120+AB120-(SUM(actual1[[#This Row],[Corporation Tax]:[Other Taxes]])-actual1[[#This Row],[Surcharge for financing of NCCF]]-actual1[[#This Row],[Devolution to State]]+SUM(P120:R120)+SUM(S120:T120)) -> 1501365 | AH120: =AG120-actual1[[#This Row],[Interest Payments]] -> 620577
A121: 2023-24 | B121: Mar-24 | C121: 911055 | D121: 1010948 | E121: 33778 | F121: 820622 | G121: -4850 | H121: 5497 | I121: 141436 | J121: 233119 | K121: 305362 | L121: 425 | M121: =8096+31 -> 8127 | N121: 8774 | O121: 1129494 | P121: 38283 | Q121: 170891 | R121: 192611 | S121: 26646 | T121: 33122 | U121: 3494252 | V121: 1063872 | W121: 290443 | X121: 609677 | Y121: 238328 | Z121: 413542 | AA121: 303916 | AB121: 949195 | AE121: =actual1[[#This Row],[Revenue Expenditure]]-(SUM(actual1[[#This Row],[Corporation Tax]:[Other Taxes]])-actual1[[#This Row],[Surcharge for financing of NCCF]]-actual1[[#This Row],[Devolution to State]]+SUM(P121:R121)) -> 765216 | AF121: =AE121-actual1[[#This Row],[Grants for Creation of Capital Assets]] -> 461300 | AG121: =U121+AB121-(SUM(actual1[[#This Row],[Corporation Tax]:[Other Taxes]])-actual1[[#This Row],[Surcharge for financing of NCCF]]-actual1[[#This Row],[Devolution to State]]+SUM(P121:R121)+SUM(S121:T121)) -> 1654643 | AH121: =AG121-actual1[[#This Row],[Interest Payments]] -> 590771
A122: 2024-25 | B122: Apr-24 | C122: 36189 | D122: 98951 | E122: 3504 | F122: 91188 | G122: -2645 | H122: 292 | I122: 13042 | J122: 13956 | K122: 70 | L122: -97 | M122: 556 | N122: 133 | O122: 69875 | P122: 3531 | Q122: 3637 | R122: 20127 | S122: 1041 | T122: 0 | U122: 324235 | V122: 128263 | W122: 30524 | X122: 10480 | Y122: 36908 | Z122: 19407 | AA122: 18206 | AB122: 99235 | AE122: =actual1[[#This Row],[Revenue Expenditure]]-(SUM(actual1[[#This Row],[Corporation Tax]:[Other Taxes]])-actual1[[#This Row],[Surcharge for financing of NCCF]]-actual1[[#This Row],[Devolution to State]]+SUM(P122:R122)) -> 111942 | AF122: =AE122-actual1[[#This Row],[Grants for Creation of Capital Assets]] -> 93736 | AG122: =U122+AB122-(SUM(actual1[[#This Row],[Corporation Tax]:[Other Taxes]])-actual1[[#This Row],[Surcharge for financing of NCCF]]-actual1[[#This Row],[Devolution to State]]+SUM(P122:R122)+SUM(S122:T122)) -> 210136 | AH122: =AG122-actual1[[#This Row],[Interest Payments]] -> 81873
A123: 2024-25 | B123: May-24 | C123: 45313 | D123: 180291 | E123: 7235 | F123: 158841 | G123: -10883 | H123: 598 | I123: 24828 | J123: 28090 | K123: 24317 | L123: -87 | M123: 1086 | N123: 842 | O123: 139751 | P123: 7924 | Q123: 215829 | R123: 27969 | S123: 2083 | T123: 4 | U123: 479835 | V123: 123810 | W123: 53032 | X123: 37881 | Y123: 60607 | Z123: 54688 | AA123: 46235 | AB123: 143625 | AE123: =actual1[[#This Row],[Revenue Expenditure]]-(SUM(actual1[[#This Row],[Corporation Tax]:[Other Taxes]])-actual1[[#This Row],[Surcharge for financing of NCCF]]-actual1[[#This Row],[Devolution to State]]+SUM(P123:R123)) -> -90923 | AF123: =AE123-actual1[[#This Row],[Grants for Creation of Capital Assets]] -> -137158 | AG123: =U123+AB123-(SUM(actual1[[#This Row],[Corporation Tax]:[Other Taxes]])-actual1[[#This Row],[Surcharge for financing of NCCF]]-actual1[[#This Row],[Devolution to State]]+SUM(P123:R123)+SUM(S123:T123)) -> 50615 | AH123: =AG123-actual1[[#This Row],[Interest Payments]] -> -73195
A124: 2024-25 | B124: Jun-24 | C124: 174774 | D124: 287336 | E124: 11606 | F124: 228328 | G124: -10176 | H124: 877 | I124: 37768 | J124: 47065 | K124: 51357 | L124: -38 | M124: 1900 | N124: 1662 | O124: 279502 | P124: 11715 | Q124: 224325 | R124: 44004 | S124: 4516 | T124: 4 | U124: 788858 | V124: 264052 | W124: 73712 | X124: 63299 | Y124: 82097 | Z124: 90174 | AA124: 58961 | AB124: 181051 | AE124: =actual1[[#This Row],[Revenue Expenditure]]-(SUM(actual1[[#This Row],[Corporation Tax]:[Other Taxes]])-actual1[[#This Row],[Surcharge for financing of NCCF]]-actual1[[#This Row],[Devolution to State]]+SUM(P124:R124)) -> -40819 | AF124: =AE124-actual1[[#This Row],[Grants for Creation of Capital Assets]] -> -99780 | AG124: =U124+AB124-(SUM(actual1[[#This Row],[Corporation Tax]:[Other Taxes]])-actual1[[#This Row],[Surcharge for financing of NCCF]]-actual1[[#This Row],[Devolution to State]]+SUM(P124:R124)+SUM(S124:T124)) -> 135712 | AH124: =AG124-actual1[[#This Row],[Interest Payments]] -> -128340
A125: 2024-25 | B125: Jul-24 | C125: 184574 | D125: 394488 | E125: 16635 | F125: 300616 | G125: -10659 | H125: 934 | I125: 50547 | J125: 67522 | K125: 76812 | L125: 13 | M125: 2747 | N125: 2375 | O125: 366630 | P125: 13840 | Q125: 228823 | R125: 59133 | S125: 6381 | T125: 5 | U125: 1039091 | V125: 327887 | W125: 98753 | X125: 91422 | Y125: 102506 | Z125: 125639 | AA125: 84957 | AB125: 261260 | AE125: =actual1[[#This Row],[Revenue Expenditure]]-(SUM(actual1[[#This Row],[Corporation Tax]:[Other Taxes]])-actual1[[#This Row],[Surcharge for financing of NCCF]]-actual1[[#This Row],[Devolution to State]]+SUM(P125:R125)) -> 22071 | AF125: =AE125-actual1[[#This Row],[Grants for Creation of Capital Assets]] -> -62886 | AG125: =U125+AB125-(SUM(actual1[[#This Row],[Corporation Tax]:[Other Taxes]])-actual1[[#This Row],[Surcharge for financing of NCCF]]-actual1[[#This Row],[Devolution to State]]+SUM(P125:R125)+SUM(S125:T125)) -> 276945 | AH125: =AG125-actual1[[#This Row],[Interest Payments]] -> -50942
A126: 2024-25 | B126: Aug-24 | C126: 224639 | D126: 452286 | E126: 21607 | F126: 371222 | G126: -2446 | H126: 1286 | I126: 62462 | J126: 94329 | K126: 104006 | L126: 32 | M126: 3299 | N126: 3160 | O126: 455717 | P126: 17530 | Q126: 239695 | R126: 77242 | S126: 8046 | T126: 820 | U126: 1351367 | V126: 400160 | W126: 120192 | X126: 182174 | Y126: 126598 | Z126: 178625 | AA126: 111066 | AB126: 300987 | AE126: =actual1[[#This Row],[Revenue Expenditure]]-(SUM(actual1[[#This Row],[Corporation Tax]:[Other Taxes]])-actual1[[#This Row],[Surcharge for financing of NCCF]]-actual1[[#This Row],[Devolution to State]]+SUM(P126:R126)) -> 143055 | AF126: =AE126-actual1[[#This Row],[Grants for Creation of Capital Assets]] -> 31989 | AG126: =U126+AB126-(SUM(actual1[[#This Row],[Corporation Tax]:[Other Taxes]])-actual1[[#This Row],[Surcharge for financing of NCCF]]-actual1[[#This Row],[Devolution to State]]+SUM(P126:R126)+SUM(S126:T126)) -> 435176 | AH126: =AG126-actual1[[#This Row],[Interest Payments]] -> 35016
A127: 2024-25 | B127: Sep-24 | C127: 461506 | D127: 564517 | E127: 26156 | F127: 441220 | G127: -846 | H127: 1624 | I127: 74323 | J127: 112959 | K127: 128466 | L127: 94 | M127: 3823 | N127: 3880 | O127: 544803 | P127: 20355 | Q127: 250633 | R127: 86226 | S127: 11434 | T127: 3167 | U127: 1696528 | V127: 515010 | W127: 145181 | X127: 239296 | Y127: 148989 | Z127: 214658 | AA127: 145208 | AB127: 414966 | AE127: =actual1[[#This Row],[Revenue Expenditure]]-(SUM(actual1[[#This Row],[Corporation Tax]:[Other Taxes]])-actual1[[#This Row],[Surcharge for financing of NCCF]]-actual1[[#This Row],[Devolution to State]]+SUM(P127:R127)) -> 74155 | AF127: =AE127-actual1[[#This Row],[Grants for Creation of Capital Assets]] -> -71053 | AG127: =U127+AB127-(SUM(actual1[[#This Row],[Corporation Tax]:[Other Taxes]])-actual1[[#This Row],[Surcharge for financing of NCCF]]-actual1[[#This Row],[Devolution to State]]+SUM(P127:R127)+SUM(S127:T127)) -> 474520 | AH127: =AG127-actual1[[#This Row],[Interest Payments]] -> -40490
A128: 2024-25 | B128: Oct-24 | C128: 487862 | D128: 626454 | E128: 30687 | F128: 521599 | G128: -10448 | H128: 1947 | I128: 86482 | J128: 132112 | K128: 151190 | L128: 87 | M128: 4662 | N128: 4685 | O128: 722976 | P128: 22701 | Q128: 264278 | R128: 112315 | S128: 13275 | T128: 5532 | U128: 2007353 | V128: 596347 | W128: 170571 | X128: 286362 | Y128: 170215 | Z128: 248670 | AA128: 163690 | AB128: 466545 | AE128: =actual1[[#This Row],[Revenue Expenditure]]-(SUM(actual1[[#This Row],[Corporation Tax]:[Other Taxes]])-actual1[[#This Row],[Surcharge for financing of NCCF]]-actual1[[#This Row],[Devolution to State]]+SUM(P128:R128)) -> 303086 | AF128: =AE128-actual1[[#This Row],[Grants for Creation of Capital Assets]] -> 139396 | AG128: =U128+AB128-(SUM(actual1[[#This Row],[Corporation Tax]:[Other Taxes]])-actual1[[#This Row],[Surcharge for financing of NCCF]]-actual1[[#This Row],[Devolution to State]]+SUM(P128:R128)+SUM(S128:T128)) -> 750824 | AH128: =AG128-actual1[[#This Row],[Interest Payments]] -> 154477
A129: 2024-25 | B129: Nov-24 | C129: 511636 | D129: 700775 | E129: 35932 | F129: 603873 | G129: -27854 | H129: 2427 | I129: 99598 | J129: 154142 | K129: 175100 | L129: 96 | M129: 5250 | N129: 5477 | O129: 812063 | P129: 26842 | Q129: 279061 | R129: 121117 | S129: 14972 | T129: 8981 | U129: 2227502 | V129: 658494 | W129: 194107 | X129: 306087 | Y129: 193346 | Z129: 279211 | AA129: 178614 | AB129: 513500 | AE129: =actual1[[#This Row],[Revenue Expenditure]]-(SUM(actual1[[#This Row],[Corporation Tax]:[Other Taxes]])-actual1[[#This Row],[Surcharge for financing of NCCF]]-actual1[[#This Row],[Devolution to State]]+SUM(P129:R129)) -> 357047 | AF129: =AE129-actual1[[#This Row],[Grants for Creation of Capital Assets]] -> 178433 | AG129: =U129+AB129-(SUM(actual1[[#This Row],[Corporation Tax]:[Other Taxes]])-actual1[[#This Row],[Surcharge for financing of NCCF]]-actual1[[#This Row],[Devolution to State]]+SUM(P129:R129)+SUM(S129:T129)) -> 846594 | AH129: =AG129-actual1[[#This Row],[Interest Payments]] -> 188100
A130: 2024-25 | B130: Dec-24 | C130: 740926 | D130: 837817 | E130: 40136 | F130: 673256 | G130: -31590 | H130: 2696 | I130: 111556 | J130: 170175 | K130: 199630 | L130: 36 | M130: 5790 | N130: 6225 | O130: 901150 | P130: 29903 | Q130: 284772 | R130: 132982 | S130: 18301 | T130: 8994 | U130: 2546757 | V130: 808313 | W130: 215520 | X130: 348245 | Y130: 215263 | Z130: 306994 | AA130: 199530 | AB130: 685337 | AE130: =actual1[[#This Row],[Revenue Expenditure]]-(SUM(actual1[[#This Row],[Corporation Tax]:[Other Taxes]])-actual1[[#This Row],[Surcharge for financing of NCCF]]-actual1[[#This Row],[Devolution to State]]+SUM(P130:R130)) -> 256047 | AF130: =AE130-actual1[[#This Row],[Grants for Creation of Capital Assets]] -> 56517 | AG130: =U130+AB130-(SUM(actual1[[#This Row],[Corporation Tax]:[Other Taxes]])-actual1[[#This Row],[Surcharge for financing of NCCF]]-actual1[[#This Row],[Devolution to State]]+SUM(P130:R130)+SUM(S130:T130)) -> 914089 | AH130: =AG130-actual1[[#This Row],[Interest Payments]] -> 105776
A131: 2024-25 | B131: Jan-25 | C131: 751319 | D131: 912792 | E131: 44541 | F131: 752514 | G131: -27610 | H131: 3560 | I131: 124971 | J131: 190176 | K131: 225902 | L131: 7 | M131: =6176+8 -> 6184 | N131: 6619 | O131: 1074179 | P131: 32162 | Q131: 285868 | R131: 149600 | S131: 20205 | T131: 9019 | U131: 2812595 | V131: 875461 | W131: 242924 | X131: 410867 | Y131: 237358 | Z131: 337733 | AA131: 218396 | AB131: 757359 | AE131: =actual1[[#This Row],[Revenue Expenditure]]-(SUM(actual1[[#This Row],[Corporation Tax]:[Other Taxes]])-actual1[[#This Row],[Surcharge for financing of NCCF]]-actual1[[#This Row],[Devolution to State]]+SUM(P131:R131)) -> 441407 | AF131: =AE131-actual1[[#This Row],[Grants for Creation of Capital Assets]] -> 223011 | AG131: =U131+AB131-(SUM(actual1[[#This Row],[Corporation Tax]:[Other Taxes]])-actual1[[#This Row],[Surcharge for financing of NCCF]]-actual1[[#This Row],[Devolution to State]]+SUM(P131:R131)+SUM(S131:T131)) -> 1169542 | AH131: =AG131-actual1[[#This Row],[Interest Payments]] -> 294081
...

Sheet BERE
A1: FY | B1: Month | C1: Corporation Tax | D1: Income Tax | E1: Securities Transcation Tax | F1: CGST | G1: IGST | H1: UTGST | I1: Compensation Cess | J1: Customs | K1: Union Excise | L1: Service Tax | M1: Other Taxes | N1: Surcharge for financing of NCCF | O1: Devolution to State | P1: Interest receipts | Q1: Dividends and Profits | R1: Other Non Tax Receipts | S1: Recovery of Loans & Advances | T1: Disinvestment Receipts | U1: Revenue Expenditure | V1: Interest Payments | W1: Defence Services | X1: Grants in Aid to States & UTs | Y1: Pensions | Z1: Major Subsidies | AA1: Grants for Creation of Capital Assets | AB1: Capital Expenditure | AG1: Other Non-Debt Capital Receipts
A2: 2014-15 | B2: BE | C2: 451005 | D2: 278275 | E2: 5991 | J2: 201819 | K2: 207110 | L2: 215973 | M2: 4351 | N2: 5050 | O2: 382216 | P2: 19751 | Q2: 90229 | R2: 102525 | S2: 10527 | T2: 63425 | U2: 1568111 | V2: 427011 | W2: 229000 | X2: 70019 | Y2: 81983 | Z2: 251397 | AA2: 168104 | AB2: 226781
A3: 2014-15 | B3: RE | C3: 426079 | D3: 272607 | E3: 5992 | J3: 188713 | K3: 185480 | L3: 168132 | M3: 4388 | N3: 5120 | O3: 337808 | P3: 22166 | Q3: 88781 | R3: 106884 | S3: 10886 | T3: 31350 | U3: 1488780 | V3: 411354 | W3: 222370 | X3: 80338 | Y3: 81705 | Z3: 253913 | AA3: 131898 | AB3: 192379
A4: 2015-16 | B4: BE | C4: 470628 | D4: 320836 | E4: 6531 | J4: 208336 | K4: 229808 | L4: 209774 | M4: 3577 | N4: 5690 | O4: 523958 | P4: 23600 | Q4: 100651 | R4: 97482 | S4: 10753 | T4: 69500 | U4: 1536047 | V4: 456145 | W4: 246727 | X4: 108630 | Y4: 88521 | Z4: 227388 | AA4: 110551 | AB4: 241430
A5: 2015-16 | B5: RE | C5: 452970 | D5: 291653 | E5: 7398 | J5: 209500 | K5: 284142 | L5: 210000 | M5: 3948 | N5: 5910 | O5: 506193 | P5: 23142 | Q5: 118271 | R5: 117163 | S5: 18905 | T5: 25312 | U5: 1547673 | V5: 442620 | W5: 224636 | X5: 108312 | Y5: 95731 | Z5: 257801 | AA5: 132004 | AB5: 237718
A6: 2016-17 | B6: BE | C6: 493924 | D6: 345776 | E6: 7398 | F6: 0 | G6: 0 | H6: 0 | I6: 0 | J6: 230000 | K6: 318669 | L6: 231000 | M6: 4121 | N6: 6450 | O6: 570337 | P6: 29620 | Q6: 123780 | R6: 169521 | S6: 10634 | T6: 56500 | U6: 1731535 | V6: 492670 | W6: 162759 | X6: 275116 | Y6: 123368 | Z6: 231782 | AA6: 166840 | AB6: 246525
A7: 2016-17 | B7: RE | C7: 493923 | D7: 345776 | E7: 7398 | F7: 0 | G7: 0 | H7: 0 | I7: 0 | J7: 217000 | K7: 387368 | L7: 247500 | M7: 4277 | N7: 6450 | O7: 608000 | P7: 18149 | Q7: 153222 | R7: 163399 | S7: 11071 | T7: 45500 | U7: 1735220 | V7: 483069 | W7: 168635 | X7: 280839 | Y7: 128166 | Z7: 229716 | AA7: 171472 | AB7: 279187
A8: 2017-18 | B8: BE | C8: 538745 | D8: 433487 | E8: 7768 | F8: 0 | G8: 0 | H8: 0 | I8: 0 | J8: 245000 | K8: 406900 | L8: 275000 | M8: 4679 | N8: 10000 | O8: 674565 | P8: 19021 | Q8: 142430 | R8: 127306 | S8: 11932 | T8: 72500 | U8: 1837505 | V8: 523078 | W8: 175861 | X8: 292968 | Y8: 131201 | Z8: 240339 | AA8: 195350 | AB8: 309230
A9: 2017-18 | B9: RE | C9: 563745 | D9: 433487 | E9: 7768 | F9: 221400 | G9: 161900 | H9: 1424 | I9: 61331 | J9: 135242 | K9: 276995 | L9: 79507 | M9: 3320 | N9: 3660 | O9: 673005 | P9: 13551 | Q9: 106433 | R9: 115990 | S9: 17473 | T9: 100000 | U9: 1944999 | V9: 530843 | W9: 180608 | X9: 369010 | Y9: 147387 | Z9: 229716 | AA9: 189245 | AB9: 272751
A10: 2018-19 | B10: BE | C10: 621000 | D10: 518000 | E10: 11000 | F10: 603900 | G10: 50000 | H10: 2530 | I10: 90000 | J10: 112500 | K10: 259600 | L10: 0 | M10: 2712 | N10: 2500 | O10: 788093 | P10: 15162 | Q10: 107312 | R10: 122615 | S10: 12199 | T10: 80000 | U10: 2142283 | V10: 575795 | W10: 188723 | X10: 420591 | Y10: 168466 | Z10: 264336 | AA10: 195345 | AB10: 299930
A11: 2018-19 | B11: RE | C11: 671000 | D11: 518000 | E11: 11000 | F11: 503900 | G11: 50000 | H11: 2530 | I11: 90000 | J11: 130038 | K11: 259612 | L11: 9283 | M11: 2812 | N11: 2315 | O11: 761454 | P11: 12047 | Q11: 119265 | R11: 113964 | S11: 13155 | T11: 80000 | U11: 2141351 | V11: 587570 | W11: 191431 | X11: 389212 | Y11: 166618 | Z11: 266206 | AA11: 200300 | AB11: 315884
A12: 2019-20 | B12: BE | C12: 766000 | D12: 556200 | E12: 12800 | F12: 526000 | G12: 28000 | H12: 2768 | I12: 109343 | J12: 155904 | K12: 300000 | L12: 0 | M12: 4180 | N12: 2480 | O12: 809133 | P12: 13711 | Q12: 163528 | R12: 135940 | S12: 14828 | T12: 105000 | U12: 2448264 | V12: 660471 | W12: 201902 | X12: 467339 | Y12: 174300 | Z12: 301694 | AA12: 207333 | AB12: 338085
A13: 2019-20 | B13: RE | C13: 610500 | D13: 547000 | E13: 12500 | F13: 514000 | G13: 0 | H13: 2704 | I13: 98327 | J13: 125000 | K13: 248012 | L13: 1200 | M13: 4180 | N13: 2790 | O13: 656046 | P13: 11027 | Q13: 199893 | R13: 134594 | S13: 16605 | T13: 65000 | U13: 2350438 | V13: 625105 | W13: 205902 | X13: 475152 | Y13: 184147 | Z13: 227255 | AA13: 191737 | AB13: 348114
A14: 2020-21 | B14: BE | C14: 681000 | D14: 625000 | E14: 13000 | F14: 580000 | G14: 0 | H14: 3000 | I14: 110500 | J14: 138000 | K14: 267000 | L14: 1020 | M14: 4500 | N14: 2930 | O14: 784181 | P14: 11042 | Q14: 155395 | R14: 218580 | S14: 14967 | T14: 210000 | U14: 2630221 | V14: 708203 | W14: 209319 | X14: 562046 | Y14: 210682 | Z14: 227794 | AA14: 206500 | AB14: 412009
A15: 2020-21 | B15: RE | C15: 446000 | D15: 447000 | E15: 12000 | F15: 431000 | G15: 0 | H15: 2720 | I15: 84100 | J15: 112000 | K15: 361000 | L15: 1400 | M15: 3060 | N15: 5820 | O15: 549959 | P15: 14005 | Q15: 96544 | R15: 100103 | S15: 14497 | T15: 32000 | U15: 3011916 | V15: 692900 | W15: 209312 | X15: 559025 | Y15: 204393 | Z15: 595620 | AA15: 230376 | AB15: 438389
A16: 2021-22 | B16: BE | C16: 547000 | D16: 548500 | E16: 12500 | F16: 530000 | G16: 0 | H16: 3327 | I16: 100000 | J16: 136000 | K16: 335000 | L16: 1000 | M16: 3732 | N16: 6100 | O16: 665563 | P16: 11541 | Q16: 103538 | R16: 127949 | S16: 13000 | T16: 175000 | U16: 2929128 | V16: 809701 | W16: 212028 | X16: 605812 | Y16: 190328 | Z16: 336439 | AA16: 219112 | AB16: 554108
A17: 2021-22 | B17: RE | C17: 635000 | D17: 595000 | E17: 20000 | F17: 570000 | G17: 0 | H17: 3327 | I17: 105000 | J17: 189000 | K17: 394000 | L17: 1000 | M17: 3732 | N17: 6130 | O17: 744784 | P17: 20894 | Q17: 147353 | R17: 145544 | S17: 21975 | T17: 78000 | U17: 3168067 | V17: 813791 | W17: 229567 | X17: 587918 | Y17: 198962 | Z17: 422108 | AA17: 237685 | AB17: 601933
... A22: 2024-25 | B22: BE | C22: 1020000 | D22: 1150000 | E22: 37000 | F22: 910890 | G22: 0 | H22: 4900 | I22: 151009 | J22: 237745 | K22: 319000 | L22: 100 | M22: 9526 | N22: 9460 | O22: 1247211 | P22: 38224 | Q22: 289134 | R22: 218343 | S22: 28000 | T22: 50000 | U22: 3709401 | V22: 1162940 | W22: 282773 | X22: 641460 | Y22: 243296 | Z22: 381175 | AA22: 390778 | AB22: 1111111
A23: 2024-25 | B23: RE | C23: 980000 | D23: 1199300 | E23: 55000 | F23: 908459 | G23: 0 | H23: 4940 | I23: 153440 | J23: 235000 | K23: 305000 | L23: 100 | M23: =9516+2700 -> 12216 | N23: 9610 | O23: 1286885 | P23: 34042 | Q23: 289285 | R23: 207673 | S23: 26000 | T23: 33000 | U23: 3698058 | V23: 1137940 | W23: 297222 | X23: 594207 | Y23: 275103 | Z23: 383419 | AA23: 299891 | AB23: 1018429
A24: 2025-26 | B24: BE | C24: 1082000 | D24: 1357000 | E24: 78000 | F24: 1010890 | G24: 0 | H24: 5355 | I24: 167110 | J24: 240000 | K24: 317000 | L24: 100 | M24: 12778 | N24: 10380 | O24: 1422444 | P24: 47738 | Q24: 325000 | R24: 210262 | S24: 29000 | T24: 47000 | U24: 3944255 | V24: 1276338 | W24: 311732 | X24: 720056 | Y24: 276618 | Z24: 383407 | AA24: 427192 | AB24: 1121090

Sheet GDP
A1: FY | B1: GDP
A2: 2014-15 | B2: 12467959
A3: 2015-16 | B3: 13771874
A4: 2016-17 | B4: 15391669
A5: 2017-18 | B5: 17090042
A6: 2018-19 | B6: 18899668
A7: 2019-20 | B7: 20103593
A8: 2020-21 | B8: 19854096
A9: 2021-22 | B9: 23597399
A10: 2022-23 | B10: 26949646
A11: 2023-24 | B11: 29535667
A12: 2024-25 | B12: 33068145
A13: 2025-26 | B13: 35713886

Sheet actual2
A1: FY | B1: Month | C1: Gross Tax Revenue | D1: Net Tax Revenue | E1: Non Tax Revenue | F1: Revenue Receipts | G1: Non Debt Capital Receipts | H1: Total Receipts | I1: Other Revenue Expenditure | J1: Total Expenditure | K1: Fiscal Deficit | L1: Revenue Deficit | M1: Effective Revenue Deficit | N1: Primary Deficit
A2: =actual!A2 -> 2014-15 | B2: =actual!B2 -> Apr-14 | C2: =SUM(actual!C2:M2) -> 28794 | D2: =C2-actual!N2-actual!O2 -> 977 | E2: =SUM(actual!P2:R2) -> 5952 | F2: =SUM(D2:E2) -> 6929 | G2: =SUM(actual!S2:T2) -> 144 | H2: =SUM(F2:G2) -> 7073 | I2: =actual!U2-actual!V2-actual!W2-actual!X2-actual!Y2-actual!Z2 -> 27171 | J2: =actual!U2+actual!AB2 -> 120527 | K2: =actual2!J2-actual2!H2 -> 113454 | L2: =actual!U2-actual2!F2 -> 101155 | M2: =L2-actual!AA2 -> 91043 | N2: =K2-actual!V2 -> 90170
A3: =actual!A3 -> 2014-15 | B3: =actual!B3 -> May-14 | C3: =SUM(actual!C3:M3) -> 84516 | D3: =C3-actual!N3-actual!O3 -> 28651 | E3: =SUM(actual!P3:R3) -> 9854 | F3: =SUM(D3:E3) -> 38505 | G3: =SUM(actual!S3:T3) -> 997 | H3: =SUM(F3:G3) -> 39502 | I3: =actual!U3-actual!V3-actual!W3-actual!X3-actual!Y3-actual!Z3 -> 64885 | J3: =actual!U3+actual!AB3 -> 280339 | K3: =actual2!J3-actual2!H3 -> 240837 | L3: =actual!U3-actual2!F3 -> 205080 | M3: =L3-actual!AA3 -> 183624 | N3: =K3-actual!V3 -> 185980
A4: =actual!A4 -> 2014-15 | B4: =actual!B4 -> Jun-14 | C4: =SUM(actual!C4:M4) -> 183028 | D4: =C4-actual!N4-actual!O4 -> 99086 | E4: =SUM(actual!P4:R4) -> 15340 | F4: =SUM(D4:E4) -> 114426 | G4: =SUM(actual!S4:T4) -> 1317 | H4: =SUM(F4:G4) -> 115743 | I4: =actual!U4-actual!V4-actual!W4-actual!X4-actual!Y4-actual!Z4 -> 114347 | J4: =actual!U4+actual!AB4 -> 413603 | K4: =actual2!J4-actual2!H4 -> 297860 | L4: =actual!U4-actual2!F4 -> 249359 | M4: =L4-actual!AA4 -> 217085 | N4: =K4-actual!V4 -> 207166
A5: =actual!A5 -> 2014-15 | B5: =actual!B5 -> Jul-14 | C5: =SUM(actual!C5:M5) -> 258873 | D5: =C5-actual!N5-actual!O5 -> 146865 | E5: =SUM(actual!P5:R5) -> 28767 | F5: =SUM(D5:E5) -> 175632 | G5: =SUM(actual!S5:T5) -> 3384 | H5: =SUM(F5:G5) -> 179016 | I5: =actual!U5-actual!V5-actual!W5-actual!X5-actual!Y5-actual!Z5 -> 132929 | J5: =actual!U5+actual!AB5 -> 503940 | K5: =actual2!J5-actual2!H5 -> 324924 | L5: =actual!U5-actual2!F5 -> 266419 | M5: =L5-actual!AA5 -> 230206 | N5: =K5-actual!V5 -> 206309
A6: =actual!A6 -> 2014-15 | B6: =actual!B6 -> Aug-14 | C6: =SUM(actual!C6:M6) -> 324938 | D6: =C6-actual!N6-actual!O6 -> 185459 | E6: =SUM(actual!P6:R6) -> 84996 | F6: =SUM(D6:E6) -> 270455 | G6: =SUM(actual!S6:T6) -> 4334 | H6: =SUM(F6:G6) -> 274789 | I6: =actual!U6-actual!V6-actual!W6-actual!X6-actual!Y6-actual!Z6 -> 177154 | J6: =actual!U6+actual!AB6 -> 672718 | K6: =actual2!J6-actual2!H6 -> 397929 | L6: =actual!U6-actual2!F6 -> 324764 | M6: =L6-actual!AA6 -> 271213 | N6: =K6-actual!V6 -> 244053
A7: =actual!A7 -> 2014-15 | B7: =actual!B7 -> Sep-14 | C7: =SUM(actual!C7:M7) -> 490618 | D7: =C7-actual!N7-actual!O7 -> 323191 | E7: =SUM(actual!P7:R7) -> 94705 | F7: =SUM(D7:E7) -> 417896 | G7: =SUM(actual!S7:T7) -> 5331 | H7: =SUM(F7:G7) -> 423227 | I7: =actual!U7-actual!V7-actual!W7-actual!X7-actual!Y7-actual!Z7 -> 244595 | J7: =actual!U7+actual!AB7 -> 862053 | K7: =actual2!J7-actual2!H7 -> 438826 | L7: =actual!U7-actual2!F7 -> 345053 | M7: =L7-actual!AA7 -> 278784 | N7: =K7-actual!V7 -> 253156
A8: =actual!A8 -> 2014-15 | B8: =actual!B8 -> Oct-14 | C8: =SUM(actual!C8:M8) -> 563598 | D8: =C8-actual!N8-actual!O8 -> 368872 | E8: =SUM(actual!P8:R8) -> 111201 | F8: =SUM(D8:E8) -> 480073 | G8: =SUM(actual!S8:T8) -> 6264 | H8: =SUM(F8:G8) -> 486337 | I8: =actual!U8-actual!V8-actual!W8-actual!X8-actual!Y8-actual!Z8 -> 267504 | J8: =actual!U8+actual!AB8 -> 962089 | K8: =actual2!J8-actual2!H8 -> 475752 | L8: =actual!U8-actual2!F8 -> 372634 | M8: =L8-actual!AA8 -> 298929 | N8: =K8-actual!V8 -> 269778
A9: =actual!A9 -> 2014-15 | B9: =actual!B9 -> Nov-14 | C9: =SUM(actual!C9:M9) -> 635583 | D9: =C9-actual!N9-actual!O9 -> 413310 | E9: =SUM(actual!P9:R9) -> 128343 | F9: =SUM(D9:E9) -> 541653 | G9: =SUM(actual!S9:T9) -> 7396 | H9: =SUM(F9:G9) -> 549049 | I9: =actual!U9-actual!V9-actual!W9-actual!X9-actual!Y9-actual!Z9 -> 294608 | J9: =actual!U9+actual!AB9 -> 1074183 | K9: =actual2!J9-actual2!H9 -> 525134 | L9: =actual!U9-actual2!F9 -> 411075 | M9: =L9-actual!AA9 -> 329491 | N9: =K9-actual!V9 -> 292484
A10: =actual!A10 -> 2014-15 | B10: =actual!B10 -> Dec-14 | C10: =SUM(actual!C10:M10) -> 795686 | D10: =C10-actual!N10-actual!O10 -> 545714 | E10: =SUM(actual!P10:R10) -> 148059 | F10: =SUM(D10:E10) -> 693773 | G10: =SUM(actual!S10:T10) -> 10234 | H10: =SUM(F10:G10) -> 704007 | I10: =actual!U10-actual!V10-actual!W10-actual!X10-actual!Y10-actual!Z10 -> 347890 | J10: =actual!U10+actual!AB10 -> 1236388 | K10: =actual2!J10-actual2!H10 -> 532381 | L10: =actual!U10-actual2!F10 -> 401775 | M10: =L10-actual!AA10 -> 303912 | N10: =K10-actual!V10 -> 257161
A11: =actual!A11 -> 2014-15 | B11: =actual!B11 -> Jan-15 | C11: =SUM(actual!C11:M11) -> 872084 | D11: =C11-actual!N11-actual!O11 -> 594797 | E11: =SUM(actual!P11:R11) -> 158310 | F11: =SUM(D11:E11) -> 753107 | G11: =SUM(actual!S11:T11) -> 17022 | H11: =SUM(F11:G11) -> 770129 | I11: =actual!U11-actual!V11-actual!W11-actual!X11-actual!Y11-actual!Z11 -> 363102 | J11: =actual!U11+actual!AB11 -> 1338268 | K11: =actual2!J11-actual2!H11 -> 568139 | L11: =actual!U11-actual2!F11 -> 441506 | M11: =L11-actual!AA11 -> 339298 | N11: =K11-actual!V11 -> 255879
A12: =actual!A12 -> 2014-15 | B12: =actual!B12 -> Feb-15 | C12: =SUM(actual!C12:M12) -> 954953 | D12: =C12-actual!N12-actual!O12 -> 651419 | E12: =SUM(actual!P12:R12) -> 164819 | F12: =SUM(D12:E12) -> 816238 | G12: =SUM(actual!S12:T12) -> 40764 | H12: =SUM(F12:G12) -> 857002 | I12: =actual!U12-actual!V12-actual!W12-actual!X12-actual!Y12-actual!Z12 -> 394375 | J12: =actual!U12+actual!AB12 -> 1459536 | K12: =actual2!J12-actual2!H12 -> 602534 | L12: =actual!U12-actual2!F12 -> 483254 | M12: =L12-actual!AA12 -> 369184 | N12: =K12-actual!V12 -> 256278
A13: =actual!A13 -> 2014-15 | B13: =actual!B13 -> Mar-15 | C13: =SUM(actual!C13:M13) -> 1244884 | D13: =C13-actual!N13-actual!O13 -> 903615 | E13: =SUM(actual!P13:R13) -> 197766 | F13: =SUM(D13:E13) -> 1101381 | G13: =SUM(actual!S13:T13) -> 51475 | H13: =SUM(F13:G13) -> 1152856 | I13: =actual!U13-actual!V13-actual!W13-actual!X13-actual!Y13-actual!Z13 -> 425825 | J13: =actual!U13+actual!AB13 -> 1663673 | K13: =actual2!J13-actual2!H13 -> 510817 | L13: =actual!U13-actual2!F13 -> 365611 | M13: =L13-actual!AA13 -> 234851 | N13: =K13-actual!V13 -> 108373
... A42: =actual!A42 -> 2017-18 | B42: =actual!B42 -> Aug-17 | C42: =SUM(actual!C42:M42) -> 583626 | D42: =C42-actual!N42-actual!O42 -> 340612 | E42: =SUM(actual!P42:R42) -> 69256 | F42: =SUM(D42:E42) -> 409868 | G42: =SUM(actual!S42:T42) -> 15534 | H42: =SUM(F42:G42) -> 425402 | I42: =actual!U42-actual!V42-actual!W42-actual!X42-actual!Y42-actual!Z42 -> 171053 | J42: =actual!U42+actual!AB42 -> 950447 | K42: =actual2!J42-actual2!H42 -> 525045 | L42: =actual!U42-actual2!F42 -> 430931 | M42: =L42-actual!AA42 -> 346131 | N42: =K42-actual!V42 -> 328652
A43: =actual!A42 -> 2017-18 | B43: =actual!B42 -> Aug-17 | C43: =SUM(actual!C42:M42) -> 583626 | D43: =C43-actual!N42-actual!O42 -> 340612 | E43: =SUM(actual!P42:R42) -> 69256 | F43: =SUM(D43:E43) -> 409868 | G43: =SUM(actual!S42:T42) -> 15534 | H43: =SUM(F43:G43) -> 425402 | I43: =actual!U42-actual!V42-actual!W42-actual!X42-actual!Y42-actual!Z42 -> 171053 | J43: =actual!U42+actual!AB42 -> 950447 | K43: =actual2!J43-actual2!H43 -> 525045 | L43: =actual!U42-actual2!F43 -> 430931 | M43: =L43-actual!AA42 -> 346131 | N43: =K43-actual!V42 -> 328652
A44: =actual!A43 -> 2017-18 | B44: =actual!B43 -> Sep-17 | C44: =SUM(actual!C43:M43) -> 833840 | D44: =C44-actual!N43-actual!O43 -> 542358 | E44: =SUM(actual!P43:R43) -> 80849 | F44: =SUM(D44:E44) -> 623207 | G44: =SUM(actual!S43:T43) -> 27042 | H44: =SUM(F44:G44) -> 650249 | I44: =actual!U43-actual!V43-actual!W43-actual!X43-actual!Y43-actual!Z43 -> 222931 | J44: =actual!U43+actual!AB43 -> 1149187 | K44: =actual2!J44-actual2!H44 -> 498938 | L44: =actual!U43-actual2!F44 -> 379591 | M44: =L44-actual!AA43 -> 272999 | N44: =K44-actual!V43 -> 273172
